Workbook

Sheet Đọc trước
A1: Moonkage – Bộ tài liệu kiến trúc thông tin (IA)
A3: Cập nhật: 23/10/2026. Nguồn: Context, User Stories, Requirement v1.8 (v1.7: BR-33, BR-34, FR-54; v1.8: AC-02.3, AC-14.5, AC-14.6; cả hai ở nhánh feat/product-cake-type-brand, chưa merge), Software Design v0.6.6. Wireframe cũ S00–S10 đã xóa; chưa có wireframe nào. Áp dụng đề xuất chỉnh sửa IA ngày 23/10 (Đ2–Đ7); nhãn cấp 1 (Đ1) chờ tree test
A4: Figma user flow CHƯA đối chiếu (chưa có link). Luồng F1–F7 lấy từ Requirement mục 8.
A5: Mã trang: M = Mua hàng (web), B = Kênh người bán, Q = Quản trị, V = App Moonkage Verify.
A6: Sửa sheet 'Kiểm kê màn hình' trước khi sửa wireframe. Cột 'Phạm vi demo' và 'Quyết định' có danh sách chọn.
A8: Tổng hợp (tự tính từ sheet Kiểm kê màn hình)
A9: Khu | B9: Số trang
A10: Mua hàng (web) | B10: =COUNTIF('Kiểm kê màn hình'!B:B,"M") -> 35
A11: Kênh người bán | B11: =COUNTIF('Kiểm kê màn hình'!B:B,"B") -> 18
A12: Quản trị | B12: =COUNTIF('Kiểm kê màn hình'!B:B,"Q") -> 15
A13: App Moonkage Verify | B13: =COUNTIF('Kiểm kê màn hình'!B:B,"V") -> 5
A14: Tổng | B14: =SUM(B10:B13) -> 73
A16: Phạm vi demo | B16: Số trang
A17: Làm trọn | B17: =COUNTIF('Kiểm kê màn hình'!J:J,"Làm trọn") -> 65
A18: Đơn giản | B18: =COUNTIF('Kiểm kê màn hình'!J:J,"Đơn giản") -> 5
A19: Hoãn | B19: =COUNTIF('Kiểm kê màn hình'!J:J,"Hoãn") -> 2
A20: Cần xác nhận | B20: =COUNTIF('Kiểm kê màn hình'!J:J,"Cần xác nhận") -> 1
A22: Trang đã có wireframe | B22: =COUNTIF('Kiểm kê màn hình'!K:K,"S*") -> 0

Sheet Kiểm kê màn hình
A1: ID | B1: Khu | C1: Trang cha | D1: Tên trang (nhãn) | E1: Loại trang | F1: Đường dẫn đề xuất | G1: Ai thấy | H1: Điều kiện hiển thị | I1: FR | J1: Phạm vi demo | K1: Wireframe hiện có | L1: Quyết định | M1: Luồng | N1: Ghi chú
A2: M1.0 | B2: M | D2: Trang chủ | E2: Trang | F2: / | G2: Khách, Người mua | I2: FR-05, FR-06, FR-14, FR-16 (lối vào) | J2: Làm trọn | L2: Sửa | M2: F1, F2, F3 | N2: Năm khối theo thứ tự (Đ3): 1 chọn khu vực (khách chưa có, AC-05.3) · 2 hai thẻ lối vào kèm điều kiện thật · 3 một dòng 'Việc cần bạn' (đã đăng nhập, có việc chờ) · 4 'Có sẵn giao tới [tỉnh]' · 5 'Nhận đặt theo yêu cầu' (bảng vài đơn vị). Không có: lịch mùa, hạn chót, số liệu không tính từ dữ liệu, ngưỡng chung '30 hộp'
A3: M1.1 | B3: M | C3: M1.0 | D3: Chọn khu vực giao | E3: Hộp thoại | F3: (hộp thoại) | G3: Khách, Người mua | H3: Mở trước khi hiện sản phẩm nếu chưa có khu vực | I3: FR-03, FR-05 (AC-05.3) | J3: Làm trọn | L3: Mới | M3: F1 | N3: Người đã đăng nhập chọn từ địa chỉ đã lưu; khách chọn tỉnh/thành
A4: M2.0 | B4: M | C4: M1.0 | D4: Mua hàng có sẵn | E4: Template: danh sách | F4: /san-pham | G4: Khách, Người mua | I4: FR-06, AC-14.5 | J4: Làm trọn | L4: Mới | M4: F1, F3 | N4: Nhãn chốt theo tree test (Đ1, cây B). Lọc giá, thương hiệu, vỏ bánh, nhân bánh, Shop (chọn nhiều trong một bộ lọc = HOẶC); sắp xếp giá, đánh giá. Từ khóa khớp tên đơn vị nhận đặt hàng → khối 'Đơn vị cung cấp' tách khỏi danh sách sản phẩm, không lọc vùng giao (AC-14.5, /api/suppliers?q=). Không có kết quả → gợi ý bỏ lọc + lối Tạo yêu cầu báo giá
A5: M2.1 | B5: M | C5: M2.0 | D5: Chi tiết sản phẩm | E5: Template | F5: /san-pham/:productId | G5: Khách, Người mua | H5: Chủ của Shop: nhãn "Sản phẩm của bạn", không có nút mua (BR-22) | I5: FR-07, FR-08 | J5: Làm trọn | L5: Mới | M5: F1, F3 | N5: Có lối "Gửi yêu cầu cho Shop này" nếu người bán nhận đặt hàng
A6: M3.0 | B6: M | C6: M1.0 | D6: Đặt theo yêu cầu | E6: Trang trung chuyển | F6: /dat-theo-yeu-cau | G6: Khách, Người mua | I6: FR-14, FR-16 | J6: Làm trọn | L6: Mới | M6: F2, F3 | N6: Nhãn chốt theo tree test (Đ1, cây B). Dòng mô tả dưới nhãn: số lượng lớn, in logo hoặc hàng phải làm riêng, dù ít hộp. Giải thích 2 cách: gửi nhiều nơi (yêu cầu báo giá) hoặc chọn một đơn vị
A7: M3.1 | B7: M | C7: M3.0 | D7: Tạo yêu cầu báo giá | E7: Form | F7: /dat-theo-yeu-cau/yeu-cau-moi | G7: Người mua đã xác minh NFC | H7: Chưa xác minh → M6.4 rồi quay lại | I7: FR-16 | J7: Làm trọn | L7: Mới | M7: F2 | N7: Chính là yêu cầu mở. Không có người bán phù hợp → gợi ý chỉnh số lượng, custom, hạn giao
A8: M3.2 | B8: M | C8: M3.0 | D8: Đơn vị cung cấp | E8: Template: danh sách | F8: /don-vi-cung-cap | G8: Khách, Người mua | I8: FR-14 (AC-14.3, AC-14.6) | J8: Làm trọn | L8: Mới | M8: F3 | N8: Ô tìm theo tên (AC-14.6). Gồm cả người bán chỉ nhận đặt hàng (nhãn 'Chỉ nhận đặt hàng')
A9: M3.3 | B9: M | C9: M3.2 | D9: Trang đơn vị cung cấp | E9: Template | F9: /don-vi-cung-cap/:vendorId | G9: Khách, Người mua | H9: Tab "Hàng có sẵn" chỉ khi có Shop; tab "Nhận đặt hàng" chỉ khi nhận đặt hàng | I9: FR-14, AC-34.1 | J9: Làm trọn | L9: Mới | M9: F1, F3 | N9: Gộp "trang Shop" và "hồ sơ nhận đặt hàng" vào một trang hai tab
A10: M3.4 | B10: M | C10: M3.3 | D10: Gửi yêu cầu cho đơn vị | E10: Form | F10: /don-vi-cung-cap/:vendorId/yeu-cau | G10: Người mua đã xác minh NFC | H10: Chủ của người bán không thấy lối vào (BR-22) | I10: FR-15 | J10: Làm trọn | L10: Mới | M10: F3 | N10: Chính là yêu cầu trực tiếp. Lối vào từ M2.1, M3.3 và giỏ hàng vượt ngưỡng (AC-08.2)
A11: M4.0 | B11: M | C11: M1.0 | D11: Giỏ hàng | E11: Bước | F11: /gio-hang | G11: Người mua | H11: Không có giỏ của khách: khách bấm thêm vào giỏ → đăng nhập, rồi tự thêm và quay về (AC-02.3) | I11: FR-08, AC-02.3 | J11: Làm trọn | L11: Mới | M11: F1 | N11: Tách theo Shop, phí giao từng Shop. Giỏ thuộc tài khoản (root Cart) và BR-22 kiểm ngay lúc thêm (Đ4)
A12: M4.1 | B12: M | C12: M4.0 | D12: Thanh toán | E12: Bước | F12: /thanh-toan | G12: Người mua | I12: FR-09, FR-24, FR-13 (hoãn) | J12: Làm trọn | L12: Mới | M12: F1 | N12: Địa chỉ, xuất hóa đơn doanh nghiệp (nhập một lần cho mọi đơn), phí giao. Ô voucher ẩn trong demo
A13: M4.2 | B13: M | C13: M4.1 | D13: Cổng VNPay | E13: Ngoài hệ thống | F13: (VNPay sandbox) | G13: Người mua | I13: FR-09, FR-19, FR-22, FR-27 | J13: Làm trọn | L13: Ngoài hệ thống | M13: F1, F2, F4 | N13: Dùng chung cho mua lẻ, cọc, phần còn lại, phí mở bán
A14: M4.3 | B14: M | C14: M4.1 | D14: Kết quả thanh toán | E14: Bước | F14: /thanh-toan/ket-qua | G14: Người mua | I14: FR-09 (AC-09.7), BR-25 | J14: Làm trọn | L14: Mới | M14: F1 | N14: Hiện N đơn vừa tạo, nhóm theo lần thanh toán; chỉ hiển thị, không đổi trạng thái
A15: M5.1 | B15: M | C15: M1.0 | D15: Đăng nhập | E15: Trang | F15: /dang-nhap | G15: Khách | I15: FR-02, AC-02.3 | J15: Làm trọn | L15: Giữ | M15: — | N15: Cổng đăng nhập: nhận trang quay về và thao tác đang dở; xác nhận tài khoản (M5.3) hoặc xác minh NFC (M6.4) trước nếu cần (AC-02.3)
A16: M5.2 | B16: M | C16: M5.1 | D16: Đăng ký | E16: Form | F16: /dang-ky | G16: Khách | I16: FR-01 | J16: Đơn giản | L16: Giữ | M16: — | N16: Demo chỉ email (A-17)
A17: M5.3 | B17: M | C17: M5.2 | D17: Xác nhận tài khoản | E17: Bước | F17: /dang-ky/xac-nhan | G17: Khách | I17: FR-01 | J17: Đơn giản | L17: Giữ | M17: —
A18: M5.4 | B18: M | C18: M5.1 | D18: Quên mật khẩu | E18: Form | F18: /quen-mat-khau | G18: Khách | I18: FR-02 | J18: Làm trọn | L18: Giữ | M18: —
A19: M5.5 | B19: M | C19: M5.4 | D19: Đặt lại mật khẩu | E19: Form | F19: /dat-lai-mat-khau | G19: Khách | I19: FR-02 | J19: Làm trọn | L19: Giữ | M19: —
A20: M6.0 | B20: M | C20: M1.0 | D20: Tài khoản của tôi | E20: Trang | F20: /tai-khoan | G20: Người mua | I20: FR-02 (AC-02.2) | J20: Làm trọn | L20: Sửa | M20: F2 | N20: Khối "Việc cần bạn": maket chờ duyệt, báo giá mới, phần còn lại cần trả. Menu theo bảng nhãn
A21: M6.1 | B21: M | C21: M6.0 | D21: Đơn hàng | E21: Template: danh sách | F21: /tai-khoan/don-hang | G21: Người mua | I21: FR-10 (AC-10.3), FR-02 | J21: Làm trọn | L21: Mới | M21: F1, F2 | N21: Hai tab: Mua hàng có sẵn (nhóm theo lần thanh toán) · Đặt theo yêu cầu
A22: M6.1.1 | B22: M | C22: M6.1 | D22: Chi tiết đơn hàng có sẵn | E22: Template | F22: /tai-khoan/don-hang/:orderId | G22: Người mua | I22: FR-10, FR-11, FR-25 | J22: Làm trọn | L22: Mới | M22: F1, F5 | N22: Trạng thái, mã vận đơn, xác nhận đã nhận, đánh giá, tải hóa đơn, lối khiếu nại Cùng đường dẫn với M6.1.2: trang tải đơn rồi chọn template theo loại đơn (Đ6)
A23: M6.1.2 | B23: M | C23: M6.1 | D23: Chi tiết đơn đặt hàng | E23: Template | F23: /tai-khoan/don-hang/:orderId | G23: Người mua | I23: FR-20, FR-21, FR-22, FR-25, FR-23 (hoãn) | J23: Làm trọn | L23: Mới | M23: F2, F3, F5 | N23: Tab: Tiến độ · Maket · Thanh toán · Hóa đơn. Nút "Đặt lại" ẩn trong demo Cùng đường dẫn với M6.1.1, chọn template theo loại đơn (Đ6)
A24: M6.1.3 | B24: M | C24: M6.1.1 | D24: Khiếu nại của đơn | E24: Form + trạng thái | F24: /tai-khoan/don-hang/:orderId/khieu-nai | G24: Người mua | H24: Nút "Báo vấn đề với đơn" chỉ hiện khi đã giao và còn hạn (3 ngày nội thành, 7 ngày liên tỉnh / đặt hàng, Q-10 tạm) | I24: FR-12, FR-49 (kết quả) | J24: Làm trọn | L24: Mới | M24: F5 | N24: Chưa có khiếu nại: form lý do, mô tả, ảnh. Đã có: trạng thái, quyết định, số tiền hoàn. Lối vào từ M6.1.1 và M6.1.2
A25: M6.2 | B25: M | C25: M6.0 | D25: Yêu cầu và báo giá | E25: Template: danh sách | F25: /tai-khoan/yeu-cau | G25: Người mua | I25: FR-15, FR-16 (AC-16.3) | J25: Làm trọn | L25: Mới | M25: F2, F3 | N25: Cột loại: "Gửi nhiều nơi" / "Gửi riêng [đơn vị]"; số người bán được mời, số báo giá
A26: M6.2.1 | B26: M | C26: M6.2 | D26: Chi tiết yêu cầu và so sánh báo giá | E26: Template | F26: /tai-khoan/yeu-cau/:requestId | G26: Người mua | I26: FR-17, FR-18 (hoãn) | J26: Làm trọn | L26: Mới | M26: F2, F3 | N26: Bảng báo giá cạnh nhau. Yêu cầu đã chốt → liên kết sang đơn đặt hàng
A27: M6.2.2 | B27: M | C27: M6.2.1 | D27: Chấp nhận báo giá và đặt cọc | E27: Bước | F27: /tai-khoan/yeu-cau/:requestId/dat-coc | G27: Người mua | I27: FR-19, FR-24 | J27: Làm trọn | L27: Mới | M27: F2, F3
A28: M6.3 | B28: M | C28: M6.0 | D28: Địa chỉ giao hàng | E28: Trang | F28: /tai-khoan/dia-chi | G28: Người mua | I28: FR-03 | J28: Làm trọn | L28: Giữ | M28: —
A29: M6.3.1 | B29: M | C29: M6.3 | D29: Thêm / sửa địa chỉ | E29: Form | F29: /tai-khoan/dia-chi/:addressId | G29: Người mua | I29: FR-03 | J29: Làm trọn | L29: Giữ | M29: —
A30: M6.3.2 | B30: M | C30: M6.3 | D30: Xóa địa chỉ | E30: Hộp thoại | F30: (hộp thoại) | G30: Người mua | I30: FR-03 | J30: Làm trọn | L30: Giữ | M30: —
A31: M6.4 | B31: M | C31: M6.0 | D31: Xác minh danh tính | E31: Trang | F31: /tai-khoan/xac-minh | G31: Người mua | H31: Cũng mở như bước chen từ M3.1, M3.4, M7.1 | I31: FR-04 | J31: Làm trọn | L31: Mới | M31: F6 | N31: Mã QR, trạng thái phiên; xong tự quay về bước đang làm
A32: M6.5 | B32: M | C32: M6.0 | D32: Thông tin cá nhân | E32: Trang | F32: /tai-khoan/thong-tin | G32: Người mua | I32: FR-02, AC-04.12 | J32: Làm trọn | L32: Mới | M32: — | N32: Họ tên, email, trạng thái xác minh, số định danh đã che
A33: M6.6 | B33: M | D33: Thông báo | E33: Trang dùng chung | F33: /thong-bao | G33: Người mua, Chủ người bán | I33: NFR-10, AC-10.2, AC-21.2 | J33: Đơn giản | L33: Mới | M33: F1–F5 | N33: Dùng chung hai khu (Đ7): một hộp mỗi tài khoản, chuông ở thanh trên của khu mua hàng và Kênh người bán, lọc Mua / Bán; mỗi thông báo mở đúng trang ở đúng khu. Giữ mã M6.6 dù không còn nằm dưới Tài khoản
A34: M7.0 | B34: M | C34: M1.0 | D34: Bán hàng trên Moonkage | E34: Trang | F34: /ban-hang/gioi-thieu | G34: Khách, Người mua | H34: Ẩn khi tài khoản đã làm chủ người bán | I34: AC-26.4, AC-26.9 | J34: Làm trọn | L34: Mới | M34: F4 | N34: Điều kiện, hai cách bán, phí 200.000đ đóng sau khi duyệt; công ty liên hệ đội vận hành (BR-33)
A35: M7.1 | B35: M | C35: M7.0 | D35: Khai hồ sơ người bán | E35: Form nhiều bước | F35: /ban-hang/dang-ky | G35: Người mua đã xác minh NFC | H35: Chưa xác minh → M6.4 | I35: FR-26, BR-27, BR-33 | J35: Làm trọn | L35: Mới | M35: F4 | N35: Bước: loại hình (HKD/DNTN) → đơn vị → chủ hộ → giấy tờ → nguồn hàng, cách bán → xem lại
A36: M8.0 | B36: M | C36: M1.0 | D36: Chính sách mua bán | E36: Trang tĩnh | F36: /chinh-sach | G36: Khách, Người mua | I36: (ngoài Requirement) | J36: Cần xác nhận | L36: Mới | M36: — | N36: Thời hạn khiếu nại, giữ tiền, giao liên tỉnh. Cần nhóm duyệt trước khi thêm
A37: B1.0 | B37: B | D37: Tổng quan | E37: Trang | F37: /kenh-ban | G37: Chủ người bán | H37: Trước khi mở bán: chỉ hiện trạng thái hồ sơ và phí | I37: FR-27 | J37: Làm trọn | L37: Mới | M37: F4 | N37: Việc cần làm: đơn mới, yêu cầu mới, maket bị yêu cầu sửa, đơn chưa có hóa đơn
A38: B1.1 | B38: B | C38: B1.0 | D38: Đóng phí mở bán | E38: Bước | F38: /kenh-ban/phi-mo-ban | G38: Chủ người bán | H38: Hồ sơ đã duyệt, chưa đóng phí | I38: FR-27 (AC-27.4, 27.5), FR-53 | J38: Làm trọn | L38: Mới | M38: F4 | N38: → VNPay (M4.2)
A39: B2.0 | B39: B | D39: Đơn hàng | E39: Template: danh sách | F39: /kenh-ban/don-hang | G39: Chủ người bán | H39: Tab theo cách bán đã bật | I39: FR-32, FR-44 (AC-44.3) | J39: Làm trọn | L39: Mới | M39: F1, F2 | N39: Tab: Đơn Shop · Đơn đặt hàng. Lọc "Chưa có hóa đơn". Nhãn "Đang khiếu nại" trên dòng đơn
A40: B2.1 | B40: B | C40: B2.0 | D40: Chi tiết đơn Shop | E40: Template | F40: /kenh-ban/don-hang/:orderId | G40: Chủ người bán | H40: Có Shop | I40: FR-32, FR-44 | J40: Làm trọn | L40: Mới | M40: F1 | N40: Xác nhận → Đang giao (mã vận đơn nếu liên tỉnh) → Đã giao; gắn hóa đơn; khối Khiếu nại (xem, gửi phản hồi: đề xuất) Cùng đường dẫn với B2.2, chọn template theo loại đơn (Đ6)
...

Sheet Điều hướng
A1: Khu | B1: Loại điều hướng | C1: Thứ tự | D1: Nhãn | E1: Đích | F1: Ai thấy | G1: Ghi chú
A2: Mua hàng | B2: Toàn cục | C2: 1 | D2: Ô tìm kiếm | E2: M2.0 | F2: Mọi người | G2: Sản phẩm theo khu vực đang chọn; từ khóa khớp tên đơn vị nhận đặt hàng thì trang kết quả có thêm khối Đơn vị cung cấp, tách khỏi danh sách sản phẩm (AC-14.5, Đ2)
A3: Mua hàng | B3: Toàn cục | C3: 2 | D3: Mua hàng có sẵn | E3: M2.0 | F3: Mọi người | G3: Chốt theo tree test (Đ1, cây B)
A4: Mua hàng | B4: Toàn cục | C4: 3 | D4: Đặt theo yêu cầu ▾ | E4: M3.0 | F4: Mọi người | G4: Chốt theo tree test (Đ1, cây B). Menu con: Tạo yêu cầu báo giá (M3.1), Đơn vị cung cấp (M3.2)
A5: Mua hàng | B5: Toàn cục | C5: 4 | D5: Giao tới: [tỉnh/thành] | E5: M1.1 | F5: Mọi người
A6: Mua hàng | B6: Toàn cục | C6: 5 | D6: Giỏ hàng | E6: M4.0 | F6: Mọi người | G6: Số món. Khách bấm thì sang đăng nhập rồi quay về; không có giỏ của khách (AC-02.3, Đ4)
A7: Mua hàng | B7: Toàn cục | C7: 6 | D7: Thông báo | E7: M6.6 | F7: Đã đăng nhập | G7: Chuông dùng chung hai khu, một hộp mỗi tài khoản, lọc Mua / Bán; có aria-label (Đ7)
A8: Mua hàng | B8: Toàn cục | C8: 7 | D8: Tài khoản ▾ / Đăng nhập | E8: M6.0 / M5.1 | G8: Khách thấy Đăng nhập
A9: Menu Tài khoản | B9: Menu | C9: 1 | D9: Tổng quan | E9: M6.0 | F9: Đã đăng nhập
A10: Menu Tài khoản | B10: Menu | C10: 2 | D10: Đơn hàng | E10: M6.1 | F10: Đã đăng nhập
A11: Menu Tài khoản | B11: Menu | C11: 3 | D11: Yêu cầu và báo giá | E11: M6.2 | F11: Đã đăng nhập
A12: Menu Tài khoản | B12: Menu | C12: 4 | D12: Địa chỉ giao hàng | E12: M6.3 | F12: Đã đăng nhập
A13: Menu Tài khoản | B13: Menu | C13: 5 | D13: Xác minh danh tính | E13: M6.4 | F13: Đã đăng nhập | G13: Hiện trạng thái: chưa / đã xác minh
A14: Menu Tài khoản | B14: Menu | C14: 6 | D14: Thông tin cá nhân | E14: M6.5 | F14: Đã đăng nhập
A15: Menu Tài khoản | B15: Menu | C15: 7 | D15: Bán hàng trên Moonkage | E15: M7.0 | F15: Chưa làm chủ người bán
A16: Menu Tài khoản | B16: Menu | C16: 7 | D16: Kênh người bán | E16: B1.0 | F16: Đã làm chủ người bán (mọi trạng thái hồ sơ)
A17: Menu Tài khoản | B17: Menu | C17: 8 | D17: Đăng xuất | E17: M5.1 | F17: Đã đăng nhập
A18: Mua hàng | B18: Footer | C18: 1 | D18: Bán hàng trên Moonkage | E18: M7.0 | F18: Mọi người
A19: Mua hàng | B19: Footer | C19: 2 | D19: Chính sách mua bán | E19: M8.0 | F19: Mọi người | G19: Cần xác nhận
A20: Kênh người bán | B20: Toàn cục | C20: 1 | D20: Tổng quan | E20: B1.0 | F20: Chủ người bán
A21: Kênh người bán | B21: Toàn cục | C21: 2 | D21: Đơn hàng | E21: B2.0 | F21: Chủ người bán | G21: Ẩn trước khi mở bán
A22: Kênh người bán | B22: Toàn cục | C22: 3 | D22: Yêu cầu báo giá | E22: B3.0 | F22: Nhận đặt hàng | G22: Ẩn khi không nhận đặt hàng hoặc trước khi mở bán
A23: Kênh người bán | B23: Toàn cục | C23: 4 | D23: Sản phẩm | E23: B4.0 | F23: Có Shop | G23: Ẩn khi không có Shop hoặc trước khi mở bán
A24: Kênh người bán | B24: Toàn cục | C24: 5 | D24: Tiền | E24: B5.0 | F24: Chủ người bán | G24: Ẩn trước khi mở bán
A25: Kênh người bán | B25: Toàn cục | C25: 6 | D25: Cài đặt bán hàng | E25: B6.0 | F25: Chủ người bán
A26: Kênh người bán | B26: Toàn cục | C26: 7 | D26: Thông báo | E26: M6.6 | F26: Chủ người bán | G26: Cùng hộp với khu mua hàng, mở sẵn bộ lọc Bán (Đ7)
A27: Kênh người bán | B27: Toàn cục | C27: 8 | D27: ↩ Về trang mua hàng | E27: M1.0 | F27: Chủ người bán
A28: Mọi khu | B28: Mẫu | C28: 1 | D28: Cổng đăng nhập | E28: M5.1 → trang cũ | F28: Khách | G28: Thao tác cần tài khoản (thêm vào giỏ, gửi yêu cầu, tạo yêu cầu báo giá, khai hồ sơ người bán): đăng nhập, xác nhận tài khoản hoặc xác minh NFC nếu cần, rồi quay về. Thêm vào giỏ tự thực hiện; form mở lại với dữ liệu đã nhập để người dùng tự gửi (AC-02.3, Đ4)
A29: Mọi khu | B29: Mẫu | C29: 2 | D29: Đường dẫn chi tiết đơn | E29: /tai-khoan/don-hang/:orderId · /kenh-ban/don-hang/:orderId | F29: Người mua, Chủ người bán | G29: Một đường dẫn cho hai loại đơn; trang tải đơn rồi chọn template theo loại đơn. Mọi liên kết tới đơn chỉ cần mã đơn (Đ6)
A30: Quản trị | B30: Cục bộ | C30: 1 | D30: Lịch sử trong trang đối tượng | E30: Q2.1, Q4.1, Q5.1 | F30: Quản trị | G30: Không có trang nhật ký chung; lịch sử duyệt, giải ngân, tiến độ hiện ngay trong trang ra quyết định (Đ5)
A31: Quản trị | B31: Toàn cục | C31: 1 | D31: Tổng quan | E31: Q1.0 | F31: Quản trị
A32: Quản trị | B32: Toàn cục | C32: 2 | D32: Người bán | E32: Q2.0 | F32: Quản trị | G32: Số hồ sơ chờ
A33: Quản trị | B33: Toàn cục | C33: 3 | D33: Sản phẩm | E33: Q3.0 | F33: Quản trị
A34: Quản trị | B34: Toàn cục | C34: 4 | D34: Tiền | E34: Q4.0 | F34: Quản trị | G34: Số giải ngân + chuyển tiền chờ
A35: Quản trị | B35: Toàn cục | C35: 5 | D35: Khiếu nại | E35: Q5.0 | F35: Quản trị | G35: Số khiếu nại mở
A36: Quản trị | B36: Toàn cục | C36: 6 | D36: Cấu hình | E36: Q6.0 | F36: Quản trị

Sheet Nhãn
A1: Nhãn hiện tại | B1: Nhãn đề xuất | C1: Xuất hiện ở | D1: Lý do
A2: MoonCage | B2: Moonkage | C2: Mọi nơi | D2: Tên đúng của sản phẩm
A3: Hồ sơ (menu tài khoản) | B3: Thông tin cá nhân | C3: M6.5 | D3: Tránh trùng 'hồ sơ người bán', 'hồ sơ nhận đặt hàng'
A4: Yêu cầu (menu tài khoản) | B4: Yêu cầu và báo giá | C4: M6.2
A5: Trở thành người bán | B5: Bán hàng trên Moonkage / Kênh người bán | C5: Menu tài khoản | D5: Một vị trí, đổi nhãn theo trạng thái
A6: Yêu cầu mở | B6: Yêu cầu báo giá (nút: Tạo yêu cầu báo giá) | C6: M3.1, M6.2 | D6: Lời người dùng
A7: Yêu cầu trực tiếp | B7: Gửi yêu cầu cho [tên đơn vị]; danh sách: 'Gửi riêng [đơn vị]' | C7: M3.4, M6.2 | D7: Nói rõ gửi cho ai
A8: Mua hàng có sẵn / Đặt theo yêu cầu (nhãn cấp 1) | B8: Đã chốt 23/10 theo tree test (Đ1): cây B thắng hoặc hòa ở nhóm nhiệm vụ phân nhánh. Thay cho 'Mua lẻ' / 'Đặt số lượng lớn' | C8: Menu, M2.0, M3.0, trang chủ, tab Đơn hàng | D8: Nhãn cũ lấy số lượng làm ranh giới; BR-03 lấy 'có sẵn hay phải thỏa thuận' (vượt tồn kho, phải sản xuất, in logo, ngưỡng của từng người bán). Context mục 4 gọi hai kiểu là 'mua lẻ' và 'làm theo yêu cầu'. Requirement giữ thuật ngữ 'mua ngay' / 'đặt hàng'
A9: Hồ sơ người bán (phía người bán) | B9: Thông tin pháp lý | C9: B6.1
A10: Hồ sơ nhận đặt hàng (phía người bán) | B10: Điều kiện nhận đặt hàng | C10: B6.3 | D10: Lời US-35
A11: Maket | B11: Maket (chú thích: bản thiết kế in logo) | C11: M6.1.2, B2.2
A12: Đơn vị cung cấp | B12: Giữ; tree test so với 'Xưởng và đại lý' | C12: M3.2, M3.3 | D12: Thuật ngữ Requirement mục 12
A13: Đơn mua ngay (phía người bán) | B13: Đơn Shop | C13: B2.0 | D13: Người bán quen chữ Shop

Sheet Taxonomy
A1: Nhóm từ vựng | B1: Thuật ngữ chuẩn (hiển thị) | C1: Cấp cha | D1: Định nghĩa | E1: Từ đồng nghĩa / người dùng có thể gõ | F1: Nguồn
A2: Cách mua | B2: Mua hàng có sẵn | D2: Mua hàng có sẵn trong tồn kho, giá niêm yết, trả ngay | E2: mua ngay, mua lẻ, đặt online | F2: BR-02
A3: Cách mua | B3: Đặt theo yêu cầu | D3: Gửi yêu cầu, nhận báo giá, đặt cọc; bắt buộc khi vượt tồn kho, có custom, phải sản xuất hoặc đạt ngưỡng báo giá | E3: đặt hàng, đặt số lượng lớn, mua sỉ, đặt quà công ty, báo giá | F3: BR-03
A4: Vỏ bánh (danh mục ban đầu, quản trị sửa được – FR-54) | B4: Bánh nướng | D4: Nhóm phân loại theo vỏ; sản phẩm gắn ≥ 1, nhiều được; mã không đổi (banh-nuong…) | E4: nướng, dẻo, bánh tuyết, snow skin | F4: BR-34, A-19
A5: Vỏ bánh (danh mục ban đầu, quản trị sửa được – FR-54) | B5: Bánh dẻo | D5: Nhóm phân loại theo vỏ; sản phẩm gắn ≥ 1, nhiều được; mã không đổi (banh-nuong…) | E5: nướng, dẻo, bánh tuyết, snow skin | F5: BR-34, A-19
A6: Vỏ bánh (danh mục ban đầu, quản trị sửa được – FR-54) | B6: Bánh lạnh | D6: Nhóm phân loại theo vỏ; sản phẩm gắn ≥ 1, nhiều được; mã không đổi (banh-nuong…) | E6: nướng, dẻo, bánh tuyết, snow skin | F6: BR-34, A-19
A7: Vỏ bánh (danh mục ban đầu, quản trị sửa được – FR-54) | B7: Khác | D7: Nhóm phân loại theo vỏ; sản phẩm gắn ≥ 1, nhiều được; mã không đổi (banh-nuong…) | E7: nướng, dẻo, bánh tuyết, snow skin | F7: BR-34, A-19
A8: Nhân bánh (danh mục ban đầu, quản trị sửa được – FR-54) | B8: Thập cẩm | D8: Nhóm phân loại theo nhân; sản phẩm gắn ≥ 1, nhiều được; 'đậu xanh trứng muối' gắn hai giá trị | E8: lạp xưởng, gà quay, matcha | F8: BR-34, A-19
A9: Nhân bánh (danh mục ban đầu, quản trị sửa được – FR-54) | B9: Đậu xanh | D9: Nhóm phân loại theo nhân; sản phẩm gắn ≥ 1, nhiều được; 'đậu xanh trứng muối' gắn hai giá trị | E9: lạp xưởng, gà quay, matcha | F9: BR-34, A-19
A10: Nhân bánh (danh mục ban đầu, quản trị sửa được – FR-54) | B10: Hạt sen | D10: Nhóm phân loại theo nhân; sản phẩm gắn ≥ 1, nhiều được; 'đậu xanh trứng muối' gắn hai giá trị | E10: lạp xưởng, gà quay, matcha | F10: BR-34, A-19
A11: Nhân bánh (danh mục ban đầu, quản trị sửa được – FR-54) | B11: Đậu đỏ | D11: Nhóm phân loại theo nhân; sản phẩm gắn ≥ 1, nhiều được; 'đậu xanh trứng muối' gắn hai giá trị | E11: lạp xưởng, gà quay, matcha | F11: BR-34, A-19
A12: Nhân bánh (danh mục ban đầu, quản trị sửa được – FR-54) | B12: Khoai môn | D12: Nhóm phân loại theo nhân; sản phẩm gắn ≥ 1, nhiều được; 'đậu xanh trứng muối' gắn hai giá trị | E12: lạp xưởng, gà quay, matcha | F12: BR-34, A-19
A13: Nhân bánh (danh mục ban đầu, quản trị sửa được – FR-54) | B13: Trà xanh | D13: Nhóm phân loại theo nhân; sản phẩm gắn ≥ 1, nhiều được; 'đậu xanh trứng muối' gắn hai giá trị | E13: lạp xưởng, gà quay, matcha | F13: BR-34, A-19
... A16: Nhân bánh (danh mục ban đầu, quản trị sửa được – FR-54) | B16: Khác | D16: Nhóm phân loại theo nhân; sản phẩm gắn ≥ 1, nhiều được; 'đậu xanh trứng muối' gắn hai giá trị | E16: lạp xưởng, gà quay, matcha | F16: BR-34, A-19
A17: Custom | B17: In logo lên túi | C17: Custom | D17: Phạm vi custom duy nhất của nền tảng | E17: in logo, in tên công ty, quà có logo | F17: BR-14
A18: Custom | B18: In logo lên thiệp | C18: Custom | D18: Phạm vi custom duy nhất của nền tảng | E18: in logo, in tên công ty, quà có logo | F18: BR-14
A19: Custom | B19: In logo lên sticker | C19: Custom | D19: Phạm vi custom duy nhất của nền tảng | E19: in logo, in tên công ty, quà có logo | F19: BR-14
A20: Custom | B20: In logo lên hộp mẫu có sẵn | C20: Custom | D20: Phạm vi custom duy nhất của nền tảng | E20: in logo, in tên công ty, quà có logo | F20: BR-14
A21: Nguồn hàng | B21: Tự sản xuất | D21: Người bán tự làm bánh hay phân phối hàng của thương hiệu khác | E21: xưởng, đại lý, nhà phân phối | F21: FR-26
A22: Nguồn hàng | B22: Bán lại | D22: Người bán tự làm bánh hay phân phối hàng của thương hiệu khác | E22: xưởng, đại lý, nhà phân phối | F22: FR-26
A23: Nguồn hàng | B23: Cả hai | D23: Người bán tự làm bánh hay phân phối hàng của thương hiệu khác | E23: xưởng, đại lý, nhà phân phối | F23: FR-26
A24: Cách bán (phía người mua) | B24: Có hàng sẵn | D24: Nhãn trên M3.2, M3.3; 'Chỉ nhận đặt hàng' = không có Shop | E24: Shop, bán lẻ, bán sỉ | F24: BR-21
A25: Cách bán (phía người mua) | B25: Nhận đặt hàng | D25: Nhãn trên M3.2, M3.3; 'Chỉ nhận đặt hàng' = không có Shop | E25: Shop, bán lẻ, bán sỉ | F25: BR-21
A26: Cách bán (phía người mua) | B26: Chỉ nhận đặt hàng | D26: Nhãn trên M3.2, M3.3; 'Chỉ nhận đặt hàng' = không có Shop | E26: Shop, bán lẻ, bán sỉ | F26: BR-21
A27: Nhãn giao | B27: Giao nội thành | D27: Toàn quốc chỉ cho sản phẩm đạt tiêu chuẩn đóng gói | E27: giao trong tỉnh, ship toàn quốc | F27: BR-13
A28: Nhãn giao | B28: Giao toàn quốc | D28: Toàn quốc chỉ cho sản phẩm đạt tiêu chuẩn đóng gói | E28: giao trong tỉnh, ship toàn quốc | F28: BR-13
A29: Khu vực | B29: Tỉnh/thành theo danh mục hành chính hiện hành | D29: Đơn vị vùng giao (giá trị tạm) | E29: khu vực, tỉnh, thành phố | F29: Q-12
A30: Loại hình người bán | B30: Hộ kinh doanh | D30: Hai loại hình được khai trên hệ thống; công ty liên hệ đội vận hành | E30: HKD, DNTN | F30: BR-33
A31: Loại hình người bán | B31: Doanh nghiệp tư nhân | D31: Hai loại hình được khai trên hệ thống; công ty liên hệ đội vận hành | E31: HKD, DNTN | F31: BR-33
A32: Lý do khiếu nại | B32: Bánh sai | E32: bể, móp, sai mẫu, trễ hẹn | F32: FR-12
A33: Lý do khiếu nại | B33: Hỏng | E33: bể, móp, sai mẫu, trễ hẹn | F33: FR-12
A34: Lý do khiếu nại | B34: Giao trễ | E34: bể, móp, sai mẫu, trễ hẹn | F34: FR-12
A35: Lý do khiếu nại | B35: In sai logo | E35: bể, móp, sai mẫu, trễ hẹn | F35: FR-12
A36: Lý do khiếu nại | B36: Khác | E36: bể, móp, sai mẫu, trễ hẹn | F36: FR-12
A37: Mục đích giải ngân | B37: Nguyên liệu | E37: ứng tiền, ứng cọc | F37: FR-41
A38: Mục đích giải ngân | B38: In ấn | E38: ứng tiền, ứng cọc | F38: FR-41
A39: Mục đích giải ngân | B39: Bao bì | E39: ứng tiền, ứng cọc | F39: FR-41
A40: Mục đích giải ngân | B40: Nhập hàng | E40: ứng tiền, ứng cọc | F40: FR-41
A41: Trạng thái đơn mua lẻ | B41: Đã thanh toán | C41: Đơn hàng | D41: Đi theo thứ tự | F41: 7.1, FR-32
A42: Trạng thái đơn mua lẻ | B42: Người bán xác nhận | C42: Đơn hàng | D42: Đi theo thứ tự | F42: 7.1, FR-32
...

Sheet Mô hình nội dung
A1: Loại nội dung | B1: Trường | C1: Kiểu | D1: Bắt buộc | E1: Hiển thị ở | F1: Ghi chú
A2: Sản phẩm | B2: Tên | C2: Chuỗi | D2: Có | E2: M2.0, M2.1, B4.1
A3: Sản phẩm | B3: Ảnh | C3: File[] | D3: Có | E3: M2.0, M2.1 | F3: JPG/PNG ≤ 20 MB (NFR-08)
A4: Sản phẩm | B4: Mô tả | C4: Văn bản | D4: Có | E4: M2.1
A5: Sản phẩm | B5: Giá niêm yết | C5: Số nguyên VND | D5: Có | E5: M2.0, M2.1 | F5: Đã gồm thuế GTGT; hiển thị 245.000đ
A6: Sản phẩm | B6: Tồn kho | C6: Số nguyên ≥ 0 | D6: Có | E6: M2.1
A7: Sản phẩm | B7: Hạn dùng | C7: Ngày | D7: Có | E7: M2.1 | F7: DD/MM/YYYY
A8: Sản phẩm | B8: Thương hiệu | C8: Chuỗi | D8: Có | E8: M2.0, M2.1 | F8: Người bán thuần bán lại tự nhập; còn lại để trống thì lấy tên đơn vị (BR-12, AC-29.4)
A9: Sản phẩm | B9: Nơi sản xuất | C9: Chuỗi | D9: Có nếu bán lại | E9: M2.1 | F9: BR-12
A10: Sản phẩm | B10: Nhãn giao | C10: Danh mục | D10: Có | E10: M2.1
A11: Sản phẩm | B11: Vỏ, nhân | C11: Mã danh mục[] | D11: ≥ 1 vỏ và ≥ 1 nhân | E11: M2.0 (lọc), M2.1, B4.1 | F11: Giá trị đã ẩn vẫn hiện trên sản phẩm đã gắn (AC-54.4)
A12: Giá trị vỏ / nhân | B12: Nhóm, mã, tên, thứ tự, đang hiện | D12: Có | E12: Q6.4, bộ lọc M2.0 | F12: Không xóa, chỉ ẩn (FR-54)
A13: Sản phẩm | B13: Bậc giá theo số lượng | C13: Danh sách | D13: Không | E13: M2.1
A14: Sản phẩm | B14: Ngưỡng báo giá | C14: Số nguyên | D14: Không | E14: M2.1 (ẩn), M4.0 | F14: Chỉ khi nhận đặt hàng
A15: Đơn vị cung cấp | B15: Tên đơn vị | C15: Chuỗi | D15: Có | E15: M3.2, M3.3
A16: Đơn vị cung cấp | B16: Cách bán | C16: Danh mục | D16: Có | E16: M3.2, M3.3
A17: Đơn vị cung cấp | B17: Nguồn hàng | C17: Danh mục | D17: Có | E17: M3.3
A18: Đơn vị cung cấp | B18: Vùng giao, phí giao nội thành | C18: Danh sách, VND | D18: Có | E18: M3.3, M2.1
A19: Điều kiện nhận đặt hàng | B19: Số lượng tối thiểu | C19: Số nguyên > 0 | D19: Có | E19: M3.2, M3.3
A20: Điều kiện nhận đặt hàng | B20: Bậc giá tham khảo | C20: Danh sách | D20: Có | E20: M3.3 | F20: Ghi rõ là tham khảo (AC-14.2)
A21: Điều kiện nhận đặt hàng | B21: Thời gian chuẩn bị | C21: Số ngày | D21: Có | E21: M3.2, M3.3
A22: Điều kiện nhận đặt hàng | B22: Khả năng custom | C22: Danh mục[] | D22: Không | E22: M3.2, M3.3
A23: Điều kiện nhận đặt hàng | B23: Ưu đãi đặt sớm | C23: Văn bản | D23: Không | E23: M3.3 | F23: Chỉ là thông tin
A24: Yêu cầu | B24: Loại | C24: Gửi nhiều nơi / Gửi riêng | D24: Có | E24: M6.2, B3.0
A25: Yêu cầu | B25: Số lượng, hạn giao, địa chỉ | D25: Có | E25: M6.2.1, B3.1
A26: Yêu cầu | B26: Ngân sách | C26: VND | D26: Gửi nhiều nơi | E26: M6.2.1, B3.1
A27: Yêu cầu | B27: Nội dung custom, logo | C27: Văn bản, file | D27: Không | E27: M6.2.1, B3.1
A28: Báo giá | B28: Đơn giá, phí giao, tổng tiền | C28: VND | D28: Có | E28: M6.2.1, B3.2
A29: Báo giá | B29: Tỷ lệ cọc | C29: % | D29: Có | E29: M6.2.1
A30: Báo giá | B30: Ngày giao, cách giao | D30: Có | E30: M6.2.1
A31: Báo giá | B31: Hiệu lực đến | C31: Ngày | D31: Có | E31: M6.2.1 | F31: 1–14 ngày (Q-19 tạm)
A32: Đơn hàng | B32: Loại, mặt hàng, tiền, phí giao | D32: Có | E32: M6.1.x, B2.x
A33: Đơn hàng | B33: Thông tin hóa đơn doanh nghiệp | C33: Tên, MST, địa chỉ, email | D33: Không | E33: M6.1.x, B2.x
A34: Đơn hàng | B34: Mã vận đơn | C34: Chuỗi | D34: Có nếu liên tỉnh | E34: M6.1.1, B2.1
A35: Đơn hàng | B35: File hóa đơn | C35: File | D35: Không | E35: M6.1.x, B2.x | F35: Chưa có → 'người bán chưa lập hóa đơn'
A36: Phiên bản maket | B36: Số phiên bản, thời điểm, file | D36: Có | E36: M6.1.2, B2.2 | F36: Không ghi đè
A37: Phiên bản maket | B37: Trạng thái, ghi chú | D37: Có | E37: M6.1.2, B2.2
A38: Cập nhật tiến độ | B38: Mốc, thời điểm | D38: Có | E38: M6.1.2, B2.2
A39: Cập nhật tiến độ | B39: Ghi chú, ảnh | D39: Không | E39: M6.1.2, B2.2
A40: Khiếu nại | B40: Lý do, mô tả, ảnh | D40: Có | E40: M6.1.3, Q5.1
...

Sheet User flows
A1: Mã | B1: Luồng | C1: Nhân vật | D1: Đường đi qua các trang | E1: Nhánh / ngoại lệ | F1: Requirement mục 8
A2: F1 | B2: Mua hàng có sẵn | C2: Anh Minh; chị Lan buổi tối | D2: M1.0 → M1.1 → M2.0 → M2.1 → M5.1 (nếu là khách, rồi quay về – AC-02.3) → M4.0 → M4.1 → M4.2 → M4.3 → M6.1 → M6.1.1 | E2: Vượt tồn kho/ngưỡng ở M4.0 → F3 (M3.4) | F2: Flow 1
A3: F2 | B3: Yêu cầu báo giá có in logo | C3: Chị Lan | D3: M1.0 → M3.0 → M3.1 → [M6.4 nếu chưa xác minh] → M6.2 → M6.2.1 → M6.2.2 → M4.2 → M6.1.2 (Maket, Tiến độ, Thanh toán phần còn lại → M4.2) | E3: Phía người bán: B3.0 → B3.1 → B3.2; B2.2; B5.2. Quản trị: Q4.1 | F3: Flow 2
A4: F3 | B4: Gửi yêu cầu cho một đơn vị | C4: Chị Thảo; anh Quân; bạn Vy | D4: M2.0 (khối Đơn vị cung cấp khi gõ tên – AC-14.5) hoặc M3.2 (tìm theo tên – AC-14.6) hoặc M2.1 hoặc M4.0 → M3.3 → M3.4 → [M6.4] → M6.2 → M6.2.1 → nối F2 từ M6.2.2 | E4: Không custom → bỏ tab Maket | F4: Flow 3
A5: F4 | B5: Trở thành người bán | C5: Cô Hoa; chị Thảo; anh Quân | D5: M7.0 → [M6.4] → M7.1 → B1.0 (Đang chờ) → Q2.0 → Q2.1 → B1.0 (Đã duyệt) → B1.1 → M4.2 → B6.2 → B4.1 và/hoặc B6.3 | E5: Cần bổ sung → B6.1 nộp lại | F5: Flow 4
A6: F5 | B6: Khiếu nại | C6: Người mua; người bán; quản trị | D6: M6.1.1/M6.1.2 (nút Báo vấn đề với đơn, còn hạn) → M6.1.3 → [giữ tiền, báo người bán] → B2.1/B2.2 (xem, phản hồi: đề xuất) → Q5.0 → Q5.1 → [hoàn VNPay nếu có] → M6.6 hai bên → M6.1.3 kết quả → Q4.2 phần còn lại | E6: Quá hạn: nút ẩn. VNPay lỗi → tab Cần xử lý tay (Q5.0). Số hoàn > đang giữ: Q-01 | F6: Flow 5
A7: F6 | B7: Xác minh NFC | C7: Mọi người dùng cần đặt hàng hoặc bán | D7: (M3.1 | M3.4 | M7.1) → M6.4 → V1 → V2 → V3 → V4 → V5 → M6.4 tự cập nhật → quay lại trang xuất phát | E7: Sai thẻ → V3; khóa sau 5 lần (Q-30 tạm) | F7: Flow 6
A8: F7 | B8: Quản lý sản phẩm | C8: Anh Quân | D8: B4.0 → B4.1 (đăng / sửa) → B4.0 (ẩn / hiện); Quản trị: Q3.0 gỡ | E8: Bị gỡ → B4.1 chỉ xem | F8: Flow 7
A10: Chưa đối chiếu với user flow trên Figma (chưa có link). Khi có, thêm cột 'Khác với Figma'.

Sheet Tree test
A1: # | B1: Nhiệm vụ | C1: Nhóm | D1: Đáp án đúng (cả hai cây) | E1: Đáp án chấp nhận được | F1: Chỗ dễ phân vân (giả định) | G1: Phân nhánh cấp 1 | H1: Cây A: số người | I1: Cây A: đúng lần đầu | J1: Cây A: tỷ lệ | K1: Cây B: số người | L1: Cây B: đúng lần đầu | M1: Cây B: tỷ lệ
A2: 1 | B2: Bạn muốn mua 2 hộp bánh cho gia đình, giao trong tuần. Bạn bắt đầu từ đâu? | C2: Người mua | D2: M2.0 | G2: Có | J2: =IF(H2="","",I2/H2) | M2: =IF(K2="","",L2/K2)
A3: 2 | B3: Công ty cần 150 phần quà có logo; bạn muốn nhiều nơi cùng gửi giá để so. | C3: Người mua | D3: M3.0 › M3.1 | E3: M3.2 (hỏi từng nơi) | G3: Có | J3: =IF(H3="","",I3/H3) | M3: =IF(K3="","",L3/K3)
A4: 3 | B4: Bạn đã chọn được xưởng của cô Hoa và muốn hỏi giá 80 hộp chỉ từ xưởng đó. | C4: Người mua | D4: M3.2 › M3.3 › M3.4 | E4: M2.1 › M3.4 | F4: Nhãn 'Đơn vị cung cấp' | G4: Không | J4: =IF(H4="","",I4/H4) | M4: =IF(K4="","",L4/K4)
A5: 4 | B5: Xưởng vừa gửi bản thiết kế in logo; bạn cần xem và đồng ý. | C5: Người mua | D5: M6.1 › M6.1.2 | E5: M6.0 Việc cần bạn | F5: Có thể vào M6.2 | G5: Không | J5: =IF(H5="","",I5/H5) | M5: =IF(K5="","",L5/K5)
A6: 5 | B6: Kế toán xin chứng từ cho đơn tuần trước. | C6: Người mua | D6: M6.1 › chi tiết đơn | G6: Không | J6: =IF(H6="","",I6/H6) | M6: =IF(K6="","",L6/K6)
A7: 6 | B7: Bánh nhận được bị bể, bạn muốn được hoàn tiền. | C7: Người mua | D7: M6.1 › M6.1.1 › M6.1.3 | F7: Có thể tìm ở footer | G7: Không | J7: =IF(H7="","",I7/H7) | M7: =IF(K7="","",L7/K7)
A8: 7 | B8: Bạn chuyển văn phòng ra Đà Nẵng và muốn thấy bánh giao được tới đó. | C8: Người mua | D8: M1.1 | E8: M6.3 | G8: Không | J8: =IF(H8="","",I8/H8) | M8: =IF(K8="","",L8/K8)
A9: 8 | B9: Bạn có hộ kinh doanh và muốn bắt đầu bán bánh ở đây. | C9: Người mua | D9: M7.0 › M7.1 | G9: Không | J9: =IF(H9="","",I9/H9) | M9: =IF(K9="","",L9/K9)
A10: 9 | B10: Một khách vừa trả tiền 3 hộp; bạn cần báo đã nhận đơn. | C10: Người bán | D10: B2.0 › B2.1 | G10: Không | J10: =IF(H10="","",I10/H10) | M10: =IF(K10="","",L10/K10)
A11: 10 | B11: Bạn cần ứng trước một phần tiền cọc để mua bột và in hộp. | C11: Người bán | D11: B5.2 | E11: B2.2 | F11: Hai lối cố ý | G11: Không | J11: =IF(H11="","",I11/H11) | M11: =IF(K11="","",L11/K11)
A12: 11 | B12: Một loại bánh đã hết hàng lâu dài; bạn muốn ngừng bán nhưng giữ dữ liệu. | C12: Người bán | D12: B4.0 (Ẩn) | F12: Có thể tìm 'xóa' | G12: Không | J12: =IF(H12="","",I12/H12) | M12: =IF(K12="","",L12/K12)
A13: 12 | B13: Một xưởng mới nộp giấy tờ; bạn cần kiểm và cho phép bán. | C13: Quản trị | D13: Q2.0 › Q2.1 | E13: Q1.0 | G13: Không | J13: =IF(H13="","",I13/H13) | M13: =IF(K13="","",L13/K13)
A14: 13 | B14: Công ty cần 10 hộp bánh có in logo để tặng đối tác. Bạn bắt đầu từ đâu? | C14: Người mua | D14: M3.0 | E14: M3.1, M3.2 | F14: Số lượng nhỏ nhưng phải qua báo giá (BR-03) | G14: Có | J14: =IF(H14="","",I14/H14) | M14: =IF(K14="","",L14/K14)
A15: 14 | B15: Một đại lý gần bạn đang có sẵn 40 hộp bánh dẻo; bạn muốn mua ngay về bán trong tiệm. | C15: Người mua | D15: M2.0 | F15: Số lượng lớn nhưng mua ngay được | G15: Có | J15: =IF(H15="","",I15/H15) | M15: =IF(K15="","",L15/K15)
A17: Cây A: nhãn cấp 1 'Mua lẻ' / 'Đặt số lượng lớn'. Cây B: 'Mua hàng có sẵn' / 'Đặt theo yêu cầu'. Mọi nhãn khác giống nhau. Mỗi người chỉ làm một cây, chia ngẫu nhiên, 5–8 người mỗi cây.
A18: Nhập ở ô vàng: số người làm nhiệm vụ và số người tìm đúng ở lần bấm đầu. Ví dụ: 8 người, 6 đúng → 75%.
A20: Chỉ số (quy tắc đặt trước khi chạy) | B20: Cây A | C20: Cây B
A21: Tỷ lệ đúng ở nhóm phân nhánh (nhiệm vụ 1, 2, 13, 14) | B21: =IFERROR(SUMIFS(I2:I15,G2:G15,"Có")/SUMIFS(H2:H15,G2:G15,"Có"),"") | C21: =IFERROR(SUMIFS(L2:L15,G2:G15,"Có")/SUMIFS(K2:K15,G2:G15,"Có"),"")
A22: Số nhiệm vụ phân nhánh mà cây B kém cây A từ 2 người trở lên | C22: =SUMPRODUCT((G2:G15="Có")*(H2:H15<>"")*(K2:K15<>"")*((I2:I15)-(L2:L15)>=2)) -> 0
A23: Nhiệm vụ 13 hoặc 14 dưới 65% ở cả hai cây | C23: =IF(COUNT(J14,M14,J15,M15)<4,"",IF(OR(AND(J14<0.65,M14<0.65),AND(J15<0.65,M15<0.65)),"Có","Không"))
A24: Kết luận theo quy tắc | C24: =IF(OR(COUNT(H2:H15)=0,COUNT(K2:K15)=0),"Chưa có dữ liệu",IF(C23="Có","Xem lại cách chia cấp 1 (Đ1, phương án D)",IF(C22>=1,"Giữ nhãn A; sửa dòng mô tả; chạy lại nhiệm vụ 13","Chọn nhãn B"))) -> Chưa có dữ liệu
A25: Quy tắc: chênh 1 người coi là hòa và chọn B vì B đúng với BR-03 (K1). Cây B kém cây A từ 2 người ở một nhiệm vụ phân nhánh thì giữ A. Cả hai cây dưới 65% ở nhiệm vụ 13 hoặc 14 thì vấn đề nằm ở cách chia, không ở nhãn.

Sheet Cần xác nhận
A1: # | B1: Điểm | C1: Mức | D1: Sửa ở
A2: 1 | B2: Link Figma user flow để đối chiếu F1–F7 | C2: Mở | D2: Nhóm
A3: 2 | B3: Nhãn cấp 1 (Đ1): đã chốt 23/10 theo tree test, cây B 'Mua hàng có sẵn' / 'Đặt theo yêu cầu' | C3: Xong | D3: Tree test
A4: 3 | B4: Merge nhánh feat/product-cake-type-brand (Requirement v1.7 và v1.8) vào develop | C4: Chặn | D4: Nhóm
A5: 4 | B5: ĐÃ CHỐT: phân loại theo vỏ và nhân, danh mục do quản trị quản lý (BR-34, FR-54, v1.7) | C5: Xong | D5: Requirement
A6: 5 | B6: ĐÃ CHỐT: thương hiệu mặc định = tên đơn vị cho hàng không thuần bán lại (BR-12, AC-29.4, v1.7) | C6: Xong | D6: Requirement
A7: 6 | B7: ĐÃ CHỐT (Đ2): tìm đơn vị cung cấp theo tên — khối riêng trên trang kết quả và ô tìm trong M3.2 (AC-14.5, AC-14.6, v1.8). Đã đối chiếu: không mâu thuẫn Context mục 2, 4, 7 | C7: Xong | D7: Requirement
A8: 7 | B8: ĐÃ CHỐT (Đ4): đăng nhập xong quay về việc đang làm; không có giỏ của khách (AC-02.3, v1.8). Đã đối chiếu: không mâu thuẫn Context mục 5 | C8: Xong | D8: Requirement
A9: 8 | B9: ĐÃ CHỐT (Đ5): không thêm trang nhật ký chung; lịch sử trong Q2.1, Q4.1, Q5.1. Endpoint nhật ký trong Software Design chưa có màn hình dùng | C9: Xong | D9: IA
A10: 9 | B10: ĐÃ CHỐT (Đ6, Đ7): một đường dẫn cho hai loại đơn; một hộp thông báo dùng chung hai khu | C10: Xong | D10: IA
A11: 10 | B11: Wireframe trang chủ: theo năm khối ở M1.0 (Đ3) | C11: Mở | D11: Wireframe
A12: 11 | B12: Khi vẽ lại menu tài khoản: dùng nhãn ở sheet Nhãn | C12: Mở | D12: Wireframe
A13: 12 | B13: Có thêm trang Chính sách mua bán (M8.0)? | C13: Mở | D13: Context/Requirement
... A22: 21 | B22: Trạng thái đơn sau khi hoàn toàn bộ (Q-01) | C22: Mở | D22: Requirement
